Workbook
Name M_to_MM: '[1]WFM - Wild Oats'!$L$54
Name M_to_MM: #REF!

Sheet DCF
B2: Discounted Cash Flow Analysis
B3: (in US$ millions including shares & except per share amounts) | E3: Actuals | J3: Estimates
B5: For the fiscal year ended March 3, 2012 | E5: ='[2]Income Statement'!D5 -> 2010 | F5: =E5+1 -> 2011 | G5: =F5+1 -> 2012 | H5: =G5+1 -> 2013 | I5: =H5+1 -> 2014 | J5: =I5+1 -> 2015 | K5: =J5+1 -> 2016 | L5: =K5+1 -> 2017
B6: Unlevered Free Cash Flow
C7: EBIT | G7: 2179 | H7: 1502.435 | I7: 1319.5573 | J7: 1236.2922 | K7: 1157.2814 | L7: 1144.8517 | M7: Income Statement
C8: Depreciation & Amortization | G8: 945 | H8: 951.687 | I8: 989.28072 | J8: 1026.369 | K8: 1060.1265 | L8: 1094.7304 | M8: Income Statement
C9: Deferred Taxes | G9: 28 | H9: -30 | I9: -134 | J9: 28 | K9: -30 | L9: -134 | M9: Cash Flow
C10: Other | G10: 0 | H10: 0 | I10: 0 | J10: 0 | K10: 0 | L10: 0
C11: Changes in Working Capital | G11: 688 | H11: -296.46693 | I11: 35.936786 | J11: 26.290603 | K11: 25.764791 | L11: -12.624747 | M11: Cash Flow
C12: Capital Expenditures | G12: -766 | H12: -749.46 | I12: -770.46 | J12: -759.98 | K12: -693 | L12: -683.33 | M12: Cash Flow
C13: Taxes | H13: =-H7*$N$17 -> -508.7496 | I13: =-I7*$N$17 -> -446.82414 | J13: =-J7*$N$17 -> -418.6292 | K13: =-K7*$N$17 -> -391.87484 | L13: =-L7*$N$17 -> -387.66593 | M13: Income Statement or Calculation
B14: Total Unlevered Free Cash Flow | H14: =SUM(H7:H13) -> 869.44547 | I14: =SUM(I7:I13) -> 993.49062 | J14: =SUM(J7:J13) -> 1138.3426 | K14: =SUM(K7:K13) -> 1128.2979 | L14: =SUM(L7:L13) -> 1021.9614
B15: Net Present Value Calulation
C16: Period | H16: 1 | I16: =H16+1 -> 2 | J16: =I16+1 -> 3 | K16: =J16+1 -> 4 | L16: =K16+1 -> 5 | N16: Tax rate | P16: Shortcut NPV
C17: Discounted Cash Flow | N17: ='[3]Income statement'!H33 -> 0.33861671 | P17: =NPV(G17,H14:L14) -> 5151.5381
C18: Total Net Present Value
B19: Terminal Value
C20: EBITDA Method | K20: Cost of Capital:
D21: Exit Year EBITDA | K21: Risk Free Rate | M21: 0.028 | N21: ="Stock Price" -> Stock Price | P21: 12.95
D22: Multiple | G22: 2 | K22: Equity Risk Premium | M22: 0.06 | N22: Diluted shares | P22: 0
D23: Terminal Value | G23: =G21*G22 -> 0 | K23: Beta | M23: 1.48 | N23: Shares Outstanding | P23: 336.66748
D24: Net Present Value | G24: =G23/(1+G17)^L16 -> 0 | K24: Cost of Equity | M24: =M21+M22*M23 -> 0.1168 | N24: Equity value | P24: =P21*(P22+P23) -> 4359.8438
C25: Perpetuity Method | N25: Total debt | P25: 2226
D26: Unlevered Free Cash Flow | K26: Cost of Debt | M26: 0.07 | N26: Cash | P26: -680
D27: Growth Rate | G27: -0.02 | K27: Cost of Preferred Stock | M27: 0 | N27: Minority interest | P27: 596
D28: Terminal Value | G28: =G26*(1+G27)/(G17-G27) -> 0 | K28: WACC | M28: =M24*Q30+M26*(1-N17)*Q31 -> 0.092970091 | N28: Enterprise value | P28: =P24+P25+P26+P27 -> 6501.8438
D29: Net Present Value | G29: =G28/(1+G17)^L16 -> 0
B30: Discounted Cash Flow Total Valuation (Enterprise Value) | N30: Equity | P30: =P24 -> 4359.8438 | Q30: =P30/$P$32 -> 0.66200231
C31: EBITDA Method | N31: Debt | P31: =P25 -> 2226 | Q31: =P31/$P$32 -> 0.33799769
C32: Perpetuity Method | N32: Cap. Structure | P32: =SUM(P30:P31) -> 6585.8438
C33: Net Debt
C34: Basic Share Count (millions) | G34: =P23 -> 336.66748
C35: Est. Fair Equity Value per share EBITDA Method | G35: =(G31-G33)/G34 -> 0
C36: Est. Fair Equity Value per share Perpetuity Method | G36: =(G32-G33)/G34 -> 0

Sheet DCF (Filled In)
B2: Discounted Cash Flow Analysis
B3: (in US$ millions including shares & except per share amounts) | E3: Actuals | J3: Estimates
B5: For the fiscal year ended March 3, 2012 | E5: ='[2]Income Statement'!D5 -> 2010 | F5: =E5+1 -> 2011 | G5: =F5+1 -> 2012 | H5: =G5+1 -> 2013 | I5: =H5+1 -> 2014 | J5: =I5+1 -> 2015 | K5: =J5+1 -> 2016 | L5: =K5+1 -> 2017
B6: Unlevered Free Cash Flow
C7: EBIT | G7: 2179 | H7: 1502.435 | I7: 1319.5573 | J7: 1236.2922 | K7: 1157.2814 | L7: 1144.8517 | M7: Income Statement
C8: Depreciation & Amortization | G8: 945 | H8: 951.687 | I8: 989.28072 | J8: 1026.369 | K8: 1060.1265 | L8: 1094.7304 | M8: Income Statement
C9: Deferred Taxes | G9: 28 | H9: -30 | I9: -134 | J9: 28 | K9: -30 | L9: -134 | M9: Cash Flow
C10: Other | G10: 0 | H10: 0 | I10: 0 | J10: 0 | K10: 0 | L10: 0
C11: Changes in Working Capital | G11: 688 | H11: -296.46693 | I11: 35.936786 | J11: 26.290603 | K11: 25.764791 | L11: -12.624747 | M11: Cash Flow
C12: Capital Expenditures | G12: -766 | H12: -749.46 | I12: -770.46 | J12: -759.98 | K12: -693 | L12: -683.33 | M12: Cash Flow
C13: Taxes | H13: =-H7*$N$17 -> -508.7496 | I13: =-I7*$N$17 -> -446.82414 | J13: =-J7*$N$17 -> -418.6292 | K13: =-K7*$N$17 -> -391.87484 | L13: =-L7*$N$17 -> -387.66593 | M13: Income Statement or Calculation
B14: Total Unlevered Free Cash Flow | H14: =SUM(H7:H13) -> 869.44547 | I14: =SUM(I7:I13) -> 993.49062 | J14: =SUM(J7:J13) -> 1138.3426 | K14: =SUM(K7:K13) -> 1128.2979 | L14: =SUM(L7:L13) -> 1021.9614
B15: Net Present Value Calulation
C16: Period | H16: 1 | I16: =H16+1 -> 2 | J16: =I16+1 -> 3 | K16: =J16+1 -> 4 | L16: =K16+1 -> 5 | N16: Tax rate | P16: Shortcut NPV
C17: Discounted Cash Flow | G17: =M28 -> 0.092970091 | H17: =H14/(1+$G$17)^H16 -> 795.4888 | I17: =I14/(1+$G$17)^I16 -> 831.66268 | J17: =J14/(1+$G$17)^J16 -> 871.86283 | K17: =K14/(1+$G$17)^K16 -> 790.66167 | L17: =L14/(1+$G$17)^L16 -> 655.22899 | N17: ='[3]Income statement'!H33 -> 0.33861671 | P17: =NPV(G17,H14:L14) -> 3944.905
C18: Total Net Present Value | H18: =SUM(H17:L17) -> 3944.905
B19: Terminal Value
C20: EBITDA Method | K20: Cost of Capital:
D21: Exit Year EBITDA | G21: =L7+L8 -> 2239.5821 | K21: Risk Free Rate | M21: 0.028 | N21: ="Stock Price" -> Stock Price | P21: 12.95
D22: Multiple | G22: 7.7 | K22: Equity Risk Premium | M22: 0.06 | N22: Diluted shares | P22: 0
D23: Terminal Value | G23: =G21*G22 -> 17244.782 | K23: Beta | M23: 1.48 | N23: Shares Outstanding | P23: 336.66748
D24: Net Present Value | G24: =G23/(1+G17)^L16 -> 11056.466 | K24: Cost of Equity | M24: =M21+M22*M23 -> 0.1168 | N24: Equity value | P24: =P21*(P22+P23) -> 4359.8438
C25: Perpetuity Method | N25: Total debt | P25: 2226
D26: Unlevered Free Cash Flow | G26: =L14 -> 1021.9614 | K26: Cost of Debt | M26: 0.07 | N26: Cash | P26: -680
D27: Growth Rate | G27: 0.02 | K27: Cost of Preferred Stock | M27: 0 | N27: Minority interest | P27: 596
D28: Terminal Value | G28: =G26*(1+G27)/(G17-G27) -> 14285.313 | K28: WACC | M28: =M24*Q30+M26*(1-N17)*Q31 -> 0.092970091 | N28: Enterprise value | P28: =P24+P25+P26+P27 -> 6501.8438
D29: Net Present Value | G29: =G28/(1+G17)^L16 -> 9159.0069
B30: Discounted Cash Flow Total Valuation (Enterprise Value) | N30: Equity | P30: =P24 -> 4359.8438 | Q30: =P30/$P$32 -> 0.66200231
C31: EBITDA Method | G31: =G24+H18 -> 15001.371 | N31: Debt | P31: =P25 -> 2226 | Q31: =P31/$P$32 -> 0.33799769
C32: Perpetuity Method | G32: =G29+H18 -> 13103.912 | N32: Cap. Structure | P32: =SUM(P30:P31) -> 6585.8438
C33: Net Debt | G33: =P25+P26 -> 1546
C34: Basic Share Count (millions) | G34: =P23 -> 336.66748
C35: Est. Fair Equity Value per share EBITDA Method | G35: =(G31-G33)/G34 -> 39.966351
C36: Est. Fair Equity Value per share Perpetuity Method | G36: =(G32-G33)/G34 -> 34.330349
D39: https://www.gurufocus.com/term/ev2ebitda/BBY/EV-to-EBITDA/Best-Buy-Co-Inc | H39: Company Comparison of EBITDA Multiple

Sheet DCF Analysis (Blank)
A1: Discounted Cash Flow Analysis
A2: ='Cash Flow Statement'!A3 -> (in US$ millions) | D2: Actuals | G2: Estimates
A4: Period Ending January 31 | D4: 2010 | E4: =D4+1 -> 2011 | F4: =E4+1 -> 2012 | G4: =F4+1 -> 2013 | H4: =G4+1 -> 2014 | I4: =H4+1 -> 2015 | J4: =I4+1 -> 2016 | K4: =J4+1 -> 2017
A5: Unlevered Free Cash Flow
B6: EBIT | R6: COST OF CAPITAL
B7: Depreciation & Amortization | R7: Formulas to be Responsible for:
B8: Deferred Income Taxes | R8: WACC = | S8: Debt | T8: X Cost of Debt | U8: X (1-Tax) | V8: + | W8: Equity | X8: X Cost of Equity
B9: Other Operating Activities | M9: INCOME STATEMENT | S9: (Debt + Equity) | W9: (Debt + Equity)
B10: Net Changes in Operating Working Capital | M10: CASH FLOW
B11: Payments for property and equipment (CAPEX) | L11: <-- This will be a negative number (payment)
B12: Income tax expense | L12: <-- This will be a negative number (taxes owed) | R12: Cost of Equity = | S12: Risk Free Rate + Market Risk Premium * Beta
A13: Total Unlevered Free Cash Flow | G13: =SUM(G6:G12) -> 0 | H13: =SUM(H6:H12) -> 0 | I13: =SUM(I6:I12) -> 0 | J13: =SUM(J6:J12) -> 0 | K13: =SUM(K6:K12) -> 0
A14: Net Present Value Calulation | R14: Equity Value: | S14: Stock Price X Shares Outstanding
B15: Period | G15: 1 | H15: 2 | I15: 3 | J15: 4 | K15: 5
B16: Discounted Cash Flow | G16: =G13/(1+$F$18)^G15 -> 0 | H16: =H13/(1+$F$18)^H15 -> 0 | I16: =I13/(1+$F$18)^I15 -> 0 | J16: =J13/(1+$F$18)^J15 -> 0 | K16: =K13/(1+$F$18)^K15 -> 0 | R16: The Following Will be Given:
B17: Total Net Present Value | G17: =SUM(G16:K16) -> 0 | S17: Risk Free Rate
E18: WACC
B19: Terminal Value | S19: Market Risk Premium
B20: EBITDA Method | J20: Cost of Capital | S20: Beta
C21: Exit Year EBITDA | F21: =K6+K7 -> 0 | J21: Risk Free Rate | L21: 0.0293 | M21: Debt YE 2012 | O21: 53427 | S21: Stock Price
C22: Multiple | F22: 16 | J22: Market Risk Premium | L22: 0.06 | M22: Stock Price | O22: 73.82 | S22: Shares Outstanding / Share Count (millions)
C23: Terminal Value | F23: =F21*F22 -> 0 | J23: Beta | L23: 0.42 | M23: Shares Outstanding | O23: =3365741174/1000000 -> 3365.7412 | S23: Tax Rate
C24: Net Present Value | F24: =F23/(1+F18)^K15 -> 0 | J24: Cost of Equity | M24: Equity Value | S24: Cost of Debt
B25: Perpetuity Method | J25: Cost of Debt | L25: 0.05625 | S25: Net Debt, Non-controlling interests, preferred securities
C26: Unlevered Free Cash Flow | F26: =K13 -> 0
C27: Growth Rate | F27: 0.02 | J27: WACC
C28: Terminal Value | F28: =F26*(1+F27)/(F18-F27) -> 0
C29: Net Present Value | F29: =F28/(1+F18)^K15 -> 0
J30: Tax Rate = 33%
B31: Discounted Cash Flow Total Valuation | E31: EBITDA Method | F31: Perpetuity Method
B32: Total of Present Value of Cash Flows | E32: =G17 -> 0 | F32: =G17 -> 0
B33: Present Value of Terminal Value | E33: =F24 -> 0 | F33: =F29 -> 0
B34: Total Enterprise Value | E34: =E32+E33 -> 0 | F34: =F32+F33 -> 0
B35: Net Debt, Non-controlling interests, preferred securities | E35: 51727 | F35: =E35 -> 51727
B36: Equity Value | E36: =E34-E35 -> -51727 | F36: =F34-F35 -> -51727
B37: Share Count (millions) | E37: 3365.7412 | F37: 3365.7412 | G37: <-- SHARES OUTSTANDING IN FAR RIGHT BOX
B38: Estimated Equity Value per Share | E38: =E36/E37 -> -15.36868 | F38: =F36/F37 -> -15.36868

Sheet Income Statement
A2: Consolidated Income Statements
A3: (in US$ millions except per share amounts) | D3: Actuals | G3: Estimates
A5: Period Ending January 31 | D5: 2010 | E5: =D5+1 -> 2011 | F5: =E5+1 -> 2012 | G5: =F5+1 -> 2013 | H5: =G5+1 -> 2014 | I5: =H5+1 -> 2015 | J5: =I5+1 -> 2016 | K5: =J5+1 -> 2017
A6: Revenue
B7: Net Sales | D7: 405132 | E7: 418952 | F7: 443854
C8: % Growth | E8: =E7/D7-1 -> 0.034112339 | F8: =F7/E7-1 -> 0.05943879
B9: Membership and Other Income | D9: 2953 | E9: 2897 | F9: 3096
C10: % Growth | E10: =E9/D9-1 -> -0.018963766 | F10: =F9/E9-1 -> 0.06869175
B11: Total revenue | D11: =D7+D9 -> 408085 | E11: =E7+E9 -> 421849 | F11: =F7+F9 -> 446950 | G11: =F11*(1+G12) -> 473767 | H11: =G11*(1+H12) -> 497455.35 | I11: =H11*(1+I12) -> 517353.56 | J11: =I11*(1+J12) -> 532874.17 | K11: =J11*(1+K12) -> 543531.65
C12: Y/Y revenue growth (%) | E12: =E11/D11-1 -> 0.033728267 | F12: =F11/E11-1 -> 0.059502334 | G12: 0.06 | H12: 0.05 | I12: 0.04 | J12: 0.03 | K12: 0.02
A13: Cost of goods sold
B14: Cost of goods sold | D14: =304106 -> 304106 | E14: =314946 -> 314946 | F14: =335127 -> 335127 | G14: =G$11*G15 -> 355325.25 | H14: =H$11*H15 -> 373091.51 | I14: =I$11*I15 -> 388015.17 | J14: =J$11*J15 -> 399655.63 | K14: =K$11*K15 -> 407648.74
C15: COGS as a % of revenue | D15: =D14/D11 -> 0.74520259 | E15: =E14/E11 -> 0.74658468 | F15: =F14/F11 -> 0.7498087 | G15: 0.75 | H15: 0.75 | I15: 0.75 | J15: 0.75 | K15: 0.75
B16: Gross profit | D16: =D11-D14 -> 103979 | E16: =E11-E14 -> 106903 | F16: =F11-F14 -> 111823 | G16: =G11-G14 -> 118441.75 | H16: =H11-H14 -> 124363.84 | I16: =I11-I14 -> 129338.39 | J16: =J11-J14 -> 133218.54 | K16: =K11-K14 -> 135882.91
C17: Gross profit margin (%) | D17: =D16/D11 -> 0.25479741 | E17: =E16/E11 -> 0.25341532 | F17: =F16/F11 -> 0.2501913 | G17: =G16/G11 -> 0.25 | H17: =H16/H11 -> 0.25 | I17: =I16/I11 -> 0.25 | J17: =J16/J11 -> 0.25 | K17: =K16/K11 -> 0.25
A18: Operating expenses
B19: Selling, general and administrative | D19: =79977-7157 -> 72820 | E19: =81361-7641 -> 73720 | F19: =85265-8130 -> 77135 | G19: =G$11*G20 -> 81961.691 | H19: =H$11*H20 -> 86059.776 | I19: =I$11*I20 -> 89502.167 | J19: =J$11*J20 -> 92187.232 | K19: =K$11*K20 -> 94030.976
C20: SG&A as a % of revenue | D20: =D19/D11 -> 0.17844322 | E20: =E19/E11 -> 0.17475447 | F20: =F19/F11 -> 0.17258083 | G20: 0.173 | H20: 0.173 | I20: 0.173 | J20: 0.173 | K20: 0.173
A21: EBITDA | D21: =D16-D19 -> 31159 | E21: =E16-E19 -> 33183 | F21: =F16-F19 -> 34688 | G21: =G16-G19 -> 36480.059 | H21: =H16-H19 -> 38304.062 | I21: =I16-I19 -> 39836.224 | J21: =J16-J19 -> 41031.311 | K21: =K16-K19 -> 41851.937
C22: EBITDA margin (%) | D22: =D21/D11 -> 0.076354191 | E22: =E21/E11 -> 0.078660848 | F22: =F21/F11 -> 0.077610471 | G22: =G21/G11 -> 0.077 | H22: =H21/H11 -> 0.077 | I22: =I21/I11 -> 0.077 | J22: =J21/J11 -> 0.077 | K22: =K21/K11 -> 0.077
B23: Depreciation and amortization | D23: 7157 | E23: 7641 | F23: 8130 | G23: 8591.6633 | H23: 9188.6097 | I23: 9809.434 | J23: 10448.883 | K23: 11101.121
A24: EBIT | D24: =D21-D23 -> 24002 | E24: =E21-E23 -> 25542 | F24: =F21-F23 -> 26558 | G24: =G21-G23 -> 27888.396 | H24: =H21-H23 -> 29115.452 | I24: =I21-I23 -> 30026.79 | J24: =J21-J23 -> 30582.428 | K24: =K21-K23 -> 30750.816
C25: EBIT margin (%) | D25: =D24/D11 -> 0.058816178 | E25: =E24/E11 -> 0.060547732 | F25: =F24/F11 -> 0.059420517 | G25: =G24/G$11 -> 0.058865214 | H25: =H24/H$11 -> 0.058528775 | I25: =I24/I$11 -> 0.058039207 | J25: =J24/J$11 -> 0.057391463 | K25: =K24/K$11 -> 0.056575944
A26: Interest
B27: Interest expense (Debt) | D27: 1787 | E27: 1928 | F27: 2034 | G27: 2083.8452 | H27: 2083.8452 | I27: 2083.8452 | J27: 2083.8452 | K27: 2083.8452
B28: Interest expense (Capital Leases) | D28: 278 | E28: 277 | F28: 288 | G28: 281.6244 | H28: 281.6244 | I28: 281.6244 | J28: 281.6244 | K28: 281.6244
B29: Interest income | D29: -181 | E29: -201 | F29: -162 | G29: -168.47819 | H29: -193.32101 | I29: -234.64571 | J29: -281.80337 | K29: -344.93777
B30: Net interest expense | D30: =SUM(D27:D29) -> 1884 | E30: =SUM(E27:E29) -> 2004 | F30: =SUM(F27:F29) -> 2160 | G30: =SUM(G27:G29) -> 2196.9914 | H30: =SUM(H27:H29) -> 2172.1486 | I30: =SUM(I27:I29) -> 2130.8239 | J30: =SUM(J27:J29) -> 2083.6662 | K30: =SUM(K27:K29) -> 2020.5318
A31: EBT | D31: =D24-D30 -> 22118 | E31: =E24-E30 -> 23538 | F31: =F24-F30 -> 24398 | G31: =G24-G30 -> 25691.404 | H31: =H24-H30 -> 26943.304 | I31: =I24-I30 -> 27895.967 | J31: =J24-J30 -> 28498.762 | K31: =K24-K30 -> 28730.285
C32: EBT margin (%) | D32: =D31/D11 -> 0.054199493 | E32: =E31/E11 -> 0.055797217 | F32: =F31/F11 -> 0.054587761 | G32: =G31/G$11 -> 0.054227931 | H32: =H31/H$11 -> 0.054162255 | I32: =I31/I$11 -> 0.053920507 | J32: =J31/J$11 -> 0.053481222 | K32: =K31/K$11 -> 0.052858531
B33: Income tax expense | D33: 7156 | E33: 7579 | F33: 7944 | G33: =G31*G34 -> 8478.1634 | H33: =H31*H34 -> 8891.2902 | I33: =I31*I34 -> 9205.669 | J33: =J31*J34 -> 9404.5915 | K33: =K31*K34 -> 9480.9939
C34: Tax rate (%) | D34: =D33/D31 -> 0.32353739 | E34: =E33/E31 -> 0.32198997 | F34: =F33/F31 -> 0.32560046 | G34: 0.33 | H34: 0.33 | I34: 0.33 | J34: 0.33 | K34: 0.33
A35: Net Income (Adjusted) | D35: =D31-D33 -> 14962 | E35: =E31-E33 -> 15959 | F35: =F31-F33 -> 16454 | G35: =G31-G33 -> 17213.241 | H35: =H31-H33 -> 18052.013 | I35: =I31-I33 -> 18690.298 | J35: =J31-J33 -> 19094.171 | K35: =K31-K33 -> 19249.291
A36: Non-recurring events
B37: Discontinued operations | D37: -79 | E37: 1034 | F37: -67 | G37: 0 | H37: 0 | I37: 0 | J37: 0 | K37: 0
B38: Other | D38: 0 | E38: 0 | F38: 0 | G38: 0 | H38: 0 | I38: 0 | J38: 0 | K38: 0
B39: Total non-recurring events | D39: =SUM(D37:D38) -> -79 | E39: =SUM(E37:E38) -> 1034 | F39: =SUM(F37:F38) -> -67 | G39: =SUM(G37:G38) -> 0 | H39: =SUM(H37:H38) -> 0 | I39: =SUM(I37:I38) -> 0 | J39: =SUM(J37:J38) -> 0 | K39: =SUM(K37:K38) -> 0
A40: Net Income (After non-recurring events) | D40: =D35+D39 -> 14883 | E40: =E35+E39 -> 16993 | F40: =F35+F39 -> 16387 | G40: =G35+G39 -> 17213.241 | H40: =H35+H39 -> 18052.013 | I40: =I35+I39 -> 18690.298 | J40: =J35+J39 -> 19094.171 | K40: =K35+K39 -> 19249.291
A41: Distributions
B42: Income attributable to non-controlling interests | D42: -513 | E42: -604 | F42: -688 | G42: =-G40*G43 -> -722.95612 | H42: =-H40*H43 -> -758.18457 | I42: =-I40*I43 -> -784.9925 | J42: =-J40*J43 -> -801.95516 | K42: =-K40*K43 -> -808.47021
...

Sheet Cash Flow Statement
A2: Consolidated Statements of Cash Flows
A3: (in US$ millions) | D3: Actuals | G3: Estimates
A5: Period Ending January 31 | D5: ='Income Statement'!D5 -> 2010 | E5: ='Income Statement'!E5 -> 2011 | F5: ='Income Statement'!F5 -> 2012 | G5: ='Income Statement'!G5 -> 2013 | H5: ='Income Statement'!H5 -> 2014 | I5: ='Income Statement'!I5 -> 2015 | J5: ='Income Statement'!J5 -> 2016 | K5: ='Income Statement'!K5 -> 2017
A6: Cash flows from operating activities
B7: Net income | D7: 14883 | E7: 16993 | F7: 16387 | G7: 17213.241 | H7: 18052.013 | I7: 18690.298 | J7: 19094.171 | K7: 19249.291
B8: Loss (income) from discontinued operations | D8: 79 | E8: -1034 | F8: 67 | G8: 0 | H8: 0 | I8: 0 | J8: 0 | K8: 0
B9: Depreciation and amortization | D9: 7157 | E9: 7641 | F9: 8130 | G9: 8591.6633 | H9: 9188.6097 | I9: 9809.434 | J9: 10448.883 | K9: 11101.121
B10: Deferred income taxes | D10: -504 | E10: 651 | F10: 1050 | G10: 715.93057 | H10: 1003.5043 | I10: 790.98605 | J10: 596.32414 | K10: 411.42494
B11: Other Operating Activities | D11: 318 | E11: 1087 | F11: 398 | G11: 318 | H11: 318 | I11: 318 | J11: 318 | K11: 318
B12: Changes in operating working capital
C13: Changes in accounts receivable | D13: -297 | E13: -733 | F13: -796 | G13: 146.51444 | H13: -289.52428 | I13: -243.20039 | J13: -189.69631 | K13: -130.25813
C14: Changes in inventory | D14: 2213 | E14: -3205 | F14: -3727 | G14: -148.40375 | H14: -2043.1202 | I14: -1716.221 | J14: -1338.6523 | K14: -919.20794
C15: Changes in prepaid expenses and other | D15: 0 | E15: 0 | F15: 0 | G15: -773.85073 | H15: -122.94254 | I15: -103.27173 | J15: -80.55195 | K15: -55.312339
C16: Changes in accounts payable | D16: 1052 | E16: 2676 | F16: 2687 | G16: 701.15125 | H16: 1865.4576 | I16: 1566.9844 | J16: 1222.2478 | K16: 839.27682
C17: Changes in accrued liabilities | D17: 1348 | E17: -433 | F17: 59 | G17: 1425.7373 | H17: 978.98686 | I17: 822.34897 | J17: 641.43219 | K17: 440.45011
C18: Changes in accrued income taxes | D18: 0 | E18: 0 | F18: 0 | G18: -459.84143 | H18: 34.312475 | I18: 26.110902 | J18: 16.521617 | K18: 6.3456495
C19: Net changes in operating working capital | D19: =SUM(D13:D18) -> 4316 | E19: =SUM(E13:E18) -> -1695 | F19: =SUM(F13:F18) -> -1777 | G19: =SUM(G13:G18) -> 891.30708 | H19: =SUM(H13:H18) -> 423.1699 | I19: =SUM(I13:I18) -> 352.75114 | J19: =SUM(J13:J18) -> 271.301 | K19: =SUM(K13:K18) -> 181.29416
B20: Total cash flows from operating activities | D20: =SUM(D7:D11,D19) -> 26249 | E20: =SUM(E7:E11,E19) -> 23643 | F20: =SUM(F7:F11,F19) -> 24255 | G20: =SUM(G7:G11,G19) -> 27730.142 | H20: =SUM(H7:H11,H19) -> 28985.297 | I20: =SUM(I7:I11,I19) -> 29961.469 | J20: =SUM(J7:J11,J19) -> 30728.679 | K20: =SUM(K7:K11,K19) -> 31261.131
A21: Cash flows from investing activities
B22: Payments for property and equipment (CAPEX) | D22: -12184 | E22: -12699 | F22: -13510 | G22: -14213.01 | H22: -14923.66 | I22: -15520.607 | J22: -15986.225 | K22: -16305.95
C23: Capex as a % of Revenue | D23: =-D22/'Income Statement'!D11 -> 0.029856525 | E23: =-E22/'Income Statement'!E11 -> 0.030103189 | F23: =-F22/'Income Statement'!F11 -> 0.030227095 | G23: 0.03 | H23: 0.03 | I23: 0.03 | J23: 0.03 | K23: 0.03
B24: Proceeds from disposal of property and equipment | D24: 1002 | E24: 489 | F24: 580 | G24: 0 | H24: 0 | I24: 0 | J24: 0 | K24: 0
B25: Investments and business acquisitions, net of cash acquired | D25: 0 | E25: -202 | F25: -3548 | G25: 0 | H25: 0 | I25: 0 | J25: 0 | K25: 0
B26: Other investing activities | D26: -438 | E26: 219 | F26: -131 | G26: -438 | H26: 219 | I26: -131 | J26: -438 | K26: 219
B27: Total cash from investing activities | D27: =D22+SUM(D24:D26) -> -11620 | E27: =E22+SUM(E24:E26) -> -12193 | F27: =F22+SUM(F24:F26) -> -16609 | G27: =G22+SUM(G24:G26) -> -14651.01 | H27: =H22+SUM(H24:H26) -> -14704.66 | I27: =I22+SUM(I24:I26) -> -15651.607 | J27: =J22+SUM(J24:J26) -> -16424.225 | K27: =K22+SUM(K24:K26) -> -16086.95
A28: Cash flows from financing activities
B29: Short-term borrowings (repayments) | D29: -1033 | E29: 503 | F29: 3019 | G29: 0 | H29: 0 | I29: 0 | J29: 0 | K29: 0
B30: Long-term borrowings (repayments) | D30: =5546-6033 -> -487 | E30: =11396-4080 -> 7316 | F30: =5050-4584 -> 466 | G30: 0 | H30: 0 | I30: 0 | J30: 0 | K30: 0
B31: Long term debt due within one year | D31: 0 | E31: 0 | F31: 0 | G31: 0 | H31: 0 | I31: 0 | J31: 0 | K31: 0
B32: Capital lease obligations due within one year | D32: 0 | E32: 0 | F32: 0 | G32: 0 | H32: 0 | I32: 0 | J32: 0 | K32: 0
B33: Dividends paid | D33: -4217 | E33: -4437 | F33: -5048 | G33: -5344.6964 | H33: -5187.2864 | I33: -5029.8764 | J33: -4872.4664 | K33: -4715.0564
C34: Dividends paid ($/share) | G34: 1.59 | H34: 1.59 | I34: 1.59 | J34: 1.59 | K34: 1.59
B35: Purchase of common stock [treasury stock] | D35: -7276 | E35: -14776 | F35: -6298 | G35: -7308.18 | H35: -7308.18 | I35: -7308.18 | J35: -7308.18 | K35: -7308.18
B36: Purchase of redeemable noncontrolling interest | D36: -436 | E36: 0 | F36: 0 | G36: 0 | H36: 0 | I36: 0 | J36: 0 | K36: 0
B37: Capital Lease Obligations | D37: -346 | E37: -363 | F37: -355 | G37: 0 | H37: 0 | I37: 0 | J37: 0 | K37: 0
B38: Other | D38: -396 | E38: -271 | F38: -242 | G38: -242 | H38: -242 | I38: -242 | J38: -242 | K38: -242
B39: Total cash from financing activities | D39: =SUM(D29:D33)+SUM(D35:D38) -> -14191 | E39: =SUM(E29:E33)+SUM(E35:E38) -> -12028 | F39: =SUM(F29:F33)+SUM(F35:F38) -> -8458 | G39: =SUM(G29:G33)+SUM(G35:G38) -> -12894.876 | H39: =SUM(H29:H33)+SUM(H35:H38) -> -12737.466 | I39: =SUM(I29:I33)+SUM(I35:I38) -> -12580.056 | J39: =SUM(J29:J33)+SUM(J35:J38) -> -12422.646 | K39: =SUM(K29:K33)+SUM(K35:K38) -> -12265.236
C40: Effect of Exchange Rate on Cash | D40: 194 | E40: 66 | F40: -33 | G40: =D40 -> 194 | H40: =E40 -> 66 | I40: =F40 -> -33 | J40: =G40 -> 194 | K40: =H40 -> 66
A41: Total change in cash and cash equivalents | D41: =D20+D27+D39+D40 -> 632 | E41: =E20+E27+E39+E40 -> -512 | F41: =F20+F27+F39+F40 -> -845 | G41: =G20+G27+G39+G40 -> 378.25539 | H41: =H20+H27+H39+H40 -> 1609.1704 | I41: =I20+I27+I39+I40 -> 1696.8054 | J41: =J20+J27+J39+J40 -> 2075.8071 | K41: =K20+K27+K39+K40 -> 2974.9447
A42: SUPPLEMENTAL DATA:
...

Sheet Project Investment Example 1
A1: Lombardi Athletics
E3: Shirt Enhancement | F3: Marketing Campaign Upgrade | G3: Improved Operations Management
D5: # of items | E5: 50000 | F5: 50000 | G5: 50000
A6: Current Annual Sales | B6: =E5*E6 -> 750000 | D6: Price per Item | E6: 15 | F6: 15 | G6: 15 | M6: ROC/ROI | N6: = (Sum of Total Cash Flow - Capital Needed to Fund Project) / Capital Needed to Fund Project
D7: Incremental Sales/Wk | E7: 4000 | F7: 2000 | G7: 750
A8: Current Annual Avg Profit Rate | B8: 0.25 | M8: IRR | N8: =IRR (CashFlow Stream) | Q8: *Make sure to include initial Capital Investmnet (Year 0)
D9: Incremental Profit | E9: =$B$8*E7 -> 1000 | F9: =$B$8*F7 -> 500 | G9: =$B$8*G7 -> 187.5
A10: Growth Assumption | B10: 0.015 | D10: Capital | E10: 800000 | F10: 300000 | G10: 35000
D11: ROC | E11: =(M19-E10)/E10 -> -0.30432309 | F11: =(M20-F10)/F10 -> -0.072430789 | G11: =(M21-G10)/G10 -> 1.9814725 | M11: NPV | N11: =NPV (Discount Rate, CashFlow Stream)
A12: Discount Rate | B12: 0.04 | D12: IRR | E12: =IRR(B19:L19) -> -0.059889745 | F12: =IRR(B20:L20) -> -0.013156263 | G12: =IRR(B21:L21) -> 0.26202818
D13: NPV | E13: =NPV($B$12,C19:L19)+B19 -> -350761.18 | F13: =NPV($B$12,C20:L20)+B20 -> -75380.59 | G13: =NPV($B$12,C21:L21)+B21 -> 49232.279
A14: Weeks per Year | B14: 52
A18: Cash Flow (Incremental) | B18: Year 0 (Capital Expd) | C18: Year 1 | D18: Year 2 | E18: Year 3 | F18: Year 4 | G18: Year 5 | H18: Year 6 | I18: Year 7 | J18: Year 8 | K18: Year 9 | L18: Year 10 | M18: Sum of Years
A19: Shirt Enhancement | B19: =-E10 -> -800000 | C19: =E9*$B$14 -> 52000 | D19: =C19*(1+$B$10) -> 52780 | E19: =D19*(1+$B$10) -> 53571.7 | F19: =E19*(1+$B$10) -> 54375.275 | G19: =F19*(1+$B$10) -> 55190.905 | H19: =G19*(1+$B$10) -> 56018.768 | I19: =H19*(1+$B$10) -> 56859.05 | J19: =I19*(1+$B$10) -> 57711.935 | K19: =J19*(1+$B$10) -> 58577.615 | L19: =K19*(1+$B$10) -> 59456.279 | M19: =SUM(C19:L19) -> 556541.53
A20: Marketing Campaign Upgrade | B20: =-F10 -> -300000 | C20: =F9*$B$14 -> 26000 | D20: =C20*(1+$B$10) -> 26390 | E20: =D20*(1+$B$10) -> 26785.85 | F20: =E20*(1+$B$10) -> 27187.638 | G20: =F20*(1+$B$10) -> 27595.452 | H20: =G20*(1+$B$10) -> 28009.384 | I20: =H20*(1+$B$10) -> 28429.525 | J20: =I20*(1+$B$10) -> 28855.968 | K20: =J20*(1+$B$10) -> 29288.807 | L20: =K20*(1+$B$10) -> 29728.139 | M20: =SUM(C20:L20) -> 278270.76
A21: Improved Operations Management | B21: =-G10 -> -35000 | C21: =G9*$B$14 -> 9750 | D21: =C21*(1+$B$10) -> 9896.25 | E21: =D21*(1+$B$10) -> 10044.694 | F21: =E21*(1+$B$10) -> 10195.364 | G21: =F21*(1+$B$10) -> 10348.295 | H21: =G21*(1+$B$10) -> 10503.519 | I21: =H21*(1+$B$10) -> 10661.072 | J21: =I21*(1+$B$10) -> 10820.988 | K21: =J21*(1+$B$10) -> 10983.303 | L21: =K21*(1+$B$10) -> 11148.052 | M21: =SUM(C21:L21) -> 104351.54
